Workbook

Sheet README
A1: Illumination power at the sample plane — bench worksheet
A2: Mirrors kb/calibrations/illumination-power.yaml. Fill the YELLOW cells only.
A4: What this unblocks, and what it does not
A5: power_at_sample_mw is {} for every line of every source today, so
A6: optics.path.excitation_rate_per_s returns None and lens 5 is BLOCKED by design.
A8: UNBLOCKED by this measurement: G21 (light-driving) · G22 (total dose)
A9: STILL BLOCKED afterwards: G10 (photobleaching)
A10: G10 needs bleach_photons, which is per dye and empty for every dye. A power meter
A11: cannot supply it. Afterwards, say "G10 only" — not "lens 5 works now".
A13: Two traps, both checked on the Checks tab before any mW is written
A14: 1. The spot may be larger than the sensor.
A15: A head reads only what lands on its element. If the illuminated field at 4x
... A54: An empty cell is a valid result. A wrong one is not.

Sheet Meta
A1: Provenance — a measurement without this is not re-usable
A2: docs/02 §1: date and measurer are mandatory for anything in kb/calibrations/.
A4: Field | B4: Value | C4: What it means
A5: date | C5: YYYY-MM-DD
A6: measured_by | C6: who was at the bench
A7: meter_model
A8: head_type | C8: thermal | photodiode
A9: head_wavelength_set | C9: nm the meter was set to — note if changed per line
A10: head_aperture_mm | C10: sensor diameter (trap 1)
A11: head_position | C11: e.g. "on the stage, at the sample plane"
A12: mm_config | C12: which .cfg was loaded
A13: room_light | C13: on | off | shrouded
A14: 100x_oil_decision | C14: measured | deferred | out of scope
A15: notes

Sheet Checks
A1: Pre-checks — these gate every row on the Power tab
A3: 1. Does the illuminated spot fit inside the sensor?
A4: If FALSE for an objective, every mW at that objective is a LOWER BOUND, not a measurement.
A5: Objective | B5: Fits? (TRUE/FALSE)
A6: 4x
A7: 10x
A8: 20x
A10: 2. Is 0% the same as the shutter closed?
A11: Any difference is leakage, and belongs in the record rather than in the noise.
A12: Reading | B12: mW
A13: at 0% level
A14: shutter closed
A15: difference (leakage) | B15: =IFERROR(B13-B14,"")
A17: 3. Which state is the instrument's NORMAL running config?
A18: Every ratio on the Derived tab is taken against it.
A19: mirror | C19: in | out
A20: multiband | C20: in | out
A21: ir | C21: in | out
A22: objective | C22: e.g. 20x

Sheet Power
A1: Power at the sample plane — 13 rows per line
A2: Fill column J (mW) and, where useful, K. Everything else is the condition, already decided.
A3: Blue row = the reference every ratio is taken against. Grey row = worked example, do not fill.
A5: Block | B5: Purpose | C5: Source | D5: Line (nm) | E5: Objective | F5: Mirror | G5: Multiband | H5: IR | I5: Level % | J5: mW | K5: Notes
A6: (example) | B6: REFERENCE | C6: Aura | D6: 488 | E6: 20x | F6: in | G6: in | H6: in | I6: 100 | J6: 1.234 | K6: head centred, room dark
A8: Line 1 | B8: linearity | E8: 20x | F8: in | G8: in | H8: in | I8: 0
A9: Line 1 | B9: linearity | E9: 20x | F9: in | G9: in | H9: in | I9: 5
A10: Line 1 | B10: linearity | E10: 20x | F10: in | G10: in | H10: in | I10: 10
A11: Line 1 | B11: linearity | E11: 20x | F11: in | G11: in | H11: in | I11: 30
A12: Line 1 | B12: linearity | E12: 20x | F12: in | G12: in | H12: in | I12: 50
A13: Line 1 | B13: REFERENCE | E13: 20x | F13: in | G13: in | H13: in | I13: 100
A14: Line 1 | B14: objective | E14: 4x | F14: in | G14: in | H14: in | I14: 100
A15: Line 1 | B15: objective | E15: 10x | F15: in | G15: in | H15: in | I15: 100
A16: Line 1 | B16: element | E16: 20x | F16: out | G16: in | H16: in | I16: 100
A17: Line 1 | B17: element | E17: 20x | F17: in | G17: out | H17: in | I17: 100
A18: Line 1 | B18: element | E18: 20x | F18: in | G18: in | H18: out | I18: 100
A19: Line 1 | B19: cross-check | E19: 20x | F19: out | G19: out | H19: in | I19: 100
... A62: Line 4 | B62: cross-check | E62: 20x | F62: out | G62: out | H62: out | I62: 100

Sheet Area
A1: Illuminated area — the half a power meter does not give
A2: Image a uniform fluorescent slide or dye solution; measure the illuminated disc's diameter in pixels.
A3: In data/pixel_size.yaml only 20x is evidence: measured. 4x and 10x are nominal, so their area inherits nominal unless the pixel size is measured in the same session (python -m calibration.cli intermediate-mag <cfg>).
A5: Objective | B5: Diameter (px) | C5: um/px | D5: px evidence | E5: Shape | F5: Area (um^2) | G5: Area (cm^2)
A6: 4x | F6: =IFERROR(PI()*(B6*C6/2)^2,"") | G6: =IFERROR(F6*1E-8,"")
A7: 10x | F7: =IFERROR(PI()*(B7*C7/2)^2,"") | G7: =IFERROR(F7*1E-8,"")
A8: 20x | F8: =IFERROR(PI()*(B8*C8/2)^2,"") | G8: =IFERROR(F8*1E-8,"")
A10: nominal | measured — write it, the tier travels with the number
A11: Shape: disc | vignetted | field-filling. A vignetted field is not a disc of that diameter.

Sheet Derived
A1: Computed at the bench — nothing here is filled by hand
A2: Blank until the Power tab has values. Watch the cross-check while you measure.
A4: Block 1 | B4: =IFERROR(Power!C8&" "&Power!D8&" nm","")
A5: Linearity | F5: linear_in_level is TRUE only if these deviations stay small
A6: Level % | B6: Measured mW | C6: If linear | D6: Deviation
A7: 0 | B7: =IFERROR(Power!J8,"") | C7: =IFERROR(Power!J13*0/100,"") | D7: =IFERROR(Power!J8/(Power!J13*0/100)-1,"")
A8: 5 | B8: =IFERROR(Power!J9,"") | C8: =IFERROR(Power!J13*5/100,"") | D8: =IFERROR(Power!J9/(Power!J13*5/100)-1,"")
A9: 10 | B9: =IFERROR(Power!J10,"") | C9: =IFERROR(Power!J13*10/100,"") | D9: =IFERROR(Power!J10/(Power!J13*10/100)-1,"")
A10: 30 | B10: =IFERROR(Power!J11,"") | C10: =IFERROR(Power!J13*30/100,"") | D10: =IFERROR(Power!J11/(Power!J13*30/100)-1,"")
A11: 50 | B11: =IFERROR(Power!J12,"") | C11: =IFERROR(Power!J13*50/100,"") | D11: =IFERROR(Power!J12/(Power!J13*50/100)-1,"")
A12: 100 | B12: =IFERROR(Power!J13,"") | C12: =IFERROR(Power!J13*100/100,"") | D12: =IFERROR(Power!J13/(Power!J13*100/100)-1,"")
A14: Element transmission | F14: T = reference / (that element removed). T<1 means it attenuates.
A15: Element | B15: mW with it out | C15: T
A16: mirror | B16: =IFERROR(Power!J16,"") | C16: =IFERROR(Power!J13/Power!J16,"")
A17: multiband | B17: =IFERROR(Power!J17,"") | C17: =IFERROR(Power!J13/Power!J17,"")
A18: IR | B18: =IFERROR(Power!J18,"") | C18: =IFERROR(Power!J13/Power!J18,"")
A20: Cross-check: does the product hold? | F20: If agreement departs from 1.00, the 13-row reduction is void.
A21: Case | B21: Predicted mW | C21: Measured mW | D21: Agreement
A22: mirror + multiband out | B22: =IFERROR(Power!J13/(C16*C17),"") | C22: =IFERROR(Power!J19,"") | D22: =IFERROR(Power!J19/(Power!J13/(C16*C17)),"")
A23: all three out | B23: =IFERROR(Power!J13/(C16*C17*C18),"") | C23: =IFERROR(Power!J20,"") | D23: =IFERROR(Power!J20/(Power!J13/(C16*C17*C18)),"")
A25: Per objective, and the number the gates actually eat
A26: Objective | B26: mW @100% | C26: vs 20x | D26: Area (cm^2) | E26: Irradiance (W/cm^2)
A27: 4x | B27: =IFERROR(Power!J14,"") | C27: =IFERROR(Power!J14/Power!J13,"") | D27: =IFERROR(Area!G6,"") | E27: =IFERROR((Power!J14/1000)/Area!G6,"")
A28: 10x | B28: =IFERROR(Power!J15,"") | C28: =IFERROR(Power!J15/Power!J13,"") | D28: =IFERROR(Area!G7,"") | E28: =IFERROR((Power!J15/1000)/Area!G7,"")
A29: 20x | B29: =IFERROR(Power!J13,"") | C29: =IFERROR(Power!J13/Power!J13,"") | D29: =IFERROR(Area!G8,"") | E29: =IFERROR((Power!J13/1000)/Area!G8,"")
A32: Block 2 | B32: =IFERROR(Power!C22&" "&Power!D22&" nm","")
A33: Linearity | F33: linear_in_level is TRUE only if these deviations stay small
A34: Level % | B34: Measured mW | C34: If linear | D34: Deviation
A35: 0 | B35: =IFERROR(Power!J22,"") | C35: =IFERROR(Power!J27*0/100,"") | D35: =IFERROR(Power!J22/(Power!J27*0/100)-1,"")
A36: 5 | B36: =IFERROR(Power!J23,"") | C36: =IFERROR(Power!J27*5/100,"") | D36: =IFERROR(Power!J23/(Power!J27*5/100)-1,"")
A37: 10 | B37: =IFERROR(Power!J24,"") | C37: =IFERROR(Power!J27*10/100,"") | D37: =IFERROR(Power!J24/(Power!J27*10/100)-1,"")
A38: 30 | B38: =IFERROR(Power!J25,"") | C38: =IFERROR(Power!J27*30/100,"") | D38: =IFERROR(Power!J25/(Power!J27*30/100)-1,"")
A39: 50 | B39: =IFERROR(Power!J26,"") | C39: =IFERROR(Power!J27*50/100,"") | D39: =IFERROR(Power!J26/(Power!J27*50/100)-1,"")
A40: 100 | B40: =IFERROR(Power!J27,"") | C40: =IFERROR(Power!J27*100/100,"") | D40: =IFERROR(Power!J27/(Power!J27*100/100)-1,"")
A42: Element transmission | F42: T = reference / (that element removed). T<1 means it attenuates.
A43: Element | B43: mW with it out | C43: T
A44: mirror | B44: =IFERROR(Power!J30,"") | C44: =IFERROR(Power!J27/Power!J30,"")
A45: multiband | B45: =IFERROR(Power!J31,"") | C45: =IFERROR(Power!J27/Power!J31,"")
A46: IR | B46: =IFERROR(Power!J32,"") | C46: =IFERROR(Power!J27/Power!J32,"")
A48: Cross-check: does the product hold? | F48: If agreement departs from 1.00, the 13-row reduction is void.
...
